<?xml version='1.0'?>
<sdf version='1.7'>
  <model name='nut_and_bolt'>
    <link name='bolt'>
      <pose>0.0 0.0 0.0 0.0 0.0 0.0</pose>
      <visual name='bolt_vis'>
        <pose>0 0 0 0 0 0</pose>
        <geometry>
          <mesh>
            <uri>./bolt.obj</uri>
            <scale>0.1 0.1 0.1</scale>
          </mesh>
        </geometry>
      </visual>
      <collision name='bolt_collision'>
        <pose>0 0 0 0 0 0</pose>
        <geometry>
          <mesh>
            <uri>./bolt.obj</uri>
            <scale>0.1 0.1 0.1</scale>
          </mesh>
        </geometry>
      </collision>
      <inertial>
        <pose>0 0 0 0 0 0</pose>
        <mass>1.3</mass>
        <inertia>
          <ixx>1.1e-2</ixx>
          <ixy>0</ixy>
          <ixz>0</ixz>
          <iyy>1.1e-2</iyy>
          <iyz>0</iyz>
          <izz>1.1e-2</izz>
        </inertia>
      </inertial>
    </link>
    <link name='nut'>
      <pose>0.0 0.0 0.0 0.0 0.0 0.0</pose>
      <visual name='nut_vis'>
        <pose>0.0 0.0 0.0 0.0 0.0 0.0</pose>
        <geometry>
          <mesh>
            <uri>./nut.obj</uri>
            <scale>0.1 0.1 0.1</scale>
          </mesh>
        </geometry>
      </visual>
      <collision name='nut_collision'>
        <pose>0 0 0 0 0 0</pose>
        <geometry>
          <mesh>
            <uri>./nut.obj</uri>
            <scale>0.1 0.1 0.1</scale>
          </mesh>
        </geometry>
      </collision>
      <inertial>
        <pose>0 0 0 0 0 0</pose>
        <mass>0.3</mass>
        <inertia>
          <ixx>1.1e-2</ixx>
          <ixy>0</ixy>
          <ixz>0</ixz>
          <iyy>1.1e-2</iyy>
          <iyz>0</iyz>
          <izz>1.1e-2</izz>
        </inertia>
      </inertial>
    </link>
    <joint name='nut_to_bolt_link' type='screw'>
      <parent>bolt</parent>
      <child>nut</child>
      <screw_thread_pitch>0.08</screw_thread_pitch>
      <pose>0 0 0 0 0 0</pose>
      <axis>
        <xyz>0 0 1</xyz>
        <dynamics>
          <damping>0.5</damping>
        </dynamics>
      </axis>
    </joint>
  </model>
</sdf>
